<?xml version='1.0' encoding='utf-8'?>
<robot name="BODY_LINK">
  <link name="body_link">
    <visual>
      <geometry>
        <cylinder length="0.1875" radius="0.05625" />
      </geometry>
      <material name="red">
        <color rgba="1.0 0.0 0.0 1.0" />
      </material>
    </visual>
    <collision>
      <geometry>
        <cylinder length="0.1875" radius="0.05625" />
      </geometry>
    </collision>
    <inertial>
      <mass value="5.0" />
      <inertia ixx="0.025" ixy="0.0" ixz="0.0" iyy="0.025" iyz="0.0" izz="0.025" />
    </inertial>
  </link>
  <joint name="top_sphere_joint_body" type="fixed">
    <parent link="body_link" />
    <child link="body_joint_link" />
    <origin xyz="0 0 0.0875" rpy="1.5 0 0" />
  </joint>
  <link name="body_joint_link">
    <visual>
      <geometry>
        <sphere radius="0.05" />
      </geometry>
      <material name="black">
        <color rgba="0.0 0.0 0.0 1.0" />
      </material>
    </visual>
    <collision>
      <geometry>
        <sphere radius="0.05" />
      </geometry>
    </collision>
    <inertial>
      <mass value="0.5" />
      <inertia ixx="0.0025" ixy="0.0" ixz="0.0" iyy="0.0025" iyz="0.0" izz="0.0025" />
    </inertial>
  </link>
  <joint name="continuous_joint" type="continuous">
    <parent link="body_joint_link" />
    <child link="auxiliar" />
    <origin xyz="0 0 0" rpy="1.6 0 0" />
    <axis xyz="0 0 1" />
  </joint>
  <link name="auxiliar">
    <visual>
      <geometry>
        <cylinder length="0.07" radius="0.05" />
      </geometry>
      <material name="black">
        <color rgba="0.0 0.0 0.0 1.0" />
      </material>
    </visual>
    <collision>
      <geometry>
        <cylinder length="0.07" radius="0.05" />
      </geometry>
    </collision>
    <inertial>
      <mass value="0.5" />
      <inertia ixx="0.0025" ixy="0.0" ixz="0.0" iyy="0.0025" iyz="0.0" izz="0.0025" />
    </inertial>
  </link>
  <joint name="fixed_joint" type="fixed">
    <parent link="auxiliar" />
    <child link="limb_joint_bottom_blue_link" />
    <origin xyz="0 0 -0.15" rpy="0 0 0" />
  </joint>
  <link name="limb_joint_bottom_blue_link">
    <visual>
      <geometry>
        <sphere radius="0.03125" />
      </geometry>
      <material name="blue">
        <color rgba="0.0 0.0 1.0 1.0" />
      </material>
    </visual>
    <collision>
      <geometry>
        <sphere radius="0.03125" />
      </geometry>
    </collision>
    <inertial>
      <mass value="2.5" />
      <inertia ixx="0.0125" ixy="0.0" ixz="0.0" iyy="0.0125" iyz="0.0" izz="0.0125" />
    </inertial>
  </link>
  <joint name="bot_sphere_joint_limb" type="fixed">
    <parent link="limb_joint_bottom_blue_link" />
    <child link="limb_link" />
    <origin xyz="0 0 0.09" rpy="0 0 0" />
  </joint>
  <link name="limb_link">
    <visual>
      <geometry>
        <cylinder length="0.1875" radius="0.03125" />
      </geometry>
      <material name="blue">
        <color rgba="0.0 0.0 1.0 1.0" />
      </material>
    </visual>
    <collision>
      <geometry>
        <cylinder length="0.1875" radius="0.03125" />
      </geometry>
    </collision>
    <inertial>
      <mass value="2.5" />
      <inertia ixx="0.0125" ixy="0.0" ixz="0.0" iyy="0.0125" iyz="0.0" izz="0.0125" />
    </inertial>
  </link>
</robot>