<joint name="revolute_joint" type="revolute">
    <parent link="body_joint_link"/>
    <child link="auxiliar"/>
    <origin xyz="0 0.05 0" rpy="0.05 0 0"/>
    <axis xyz="0 0 1"/>
    <limit lower="-1.14" upper="1.14" effort="1.0" velocity="1.0"/>
  </joint>


  <link name="auxiliar">
    <visual>
      <geometry>
        <cylinder length="0.07" radius="0.05"/>
      </geometry>
      <material name="black">
        <color rgba="0.0 0.0 0.0 1.0"/>
      </material>
    </visual>
    <collision>
      <geometry>
        <sphere radius="0.05"/>
      </geometry>
    </collision>
    <inertial>
      <mass value="0.5"/>
      <inertia ixx="0.0025" ixy="0.0" ixz="0.0" iyy="0.0025" iyz="0.0" izz="0.0025"/>
    </inertial>
  </link>



  <joint name="fixed_joint" type="fixed">
    <parent link="auxiliar"/>
    <child link="limb_joint_bottom_blue_link"/>
    <origin xyz="0 0.2 0.005" rpy="1.6 0 0"/>
  </joint>
