<?xml version='1.0' encoding='utf-8'?>
<robot name="sim">
  <joint name="joint_11" type="fixed">
    <parent link="0 body_Link_CUBE" />
    <child link="Sphere_4" />
    <origin xyz="0 -0.023 0" rpy="0 0 0" />
  </joint>
  <link name="Sphere_4">
    <visual>
      <geometry>
        <sphere radius="0.01" />
      </geometry>
      <material name="black">
        <color rgba="0 0 0 1.0" />
      </material>
    </visual>
    <collision>
      <geometry>
        <sphere radius="0.01" />
      </geometry>
    </collision>
    <inertial>
      <mass value="0.004" />
      <inertia ixx="1.7e-07" ixy="0.0" ixz="0.0" iyy="1.7e-07" iyz="0.0" izz="1.7e-07" />
    </inertial>
  </link>
  <joint name="joint_12" type="revolute">
    <parent link="Sphere_4" />
    <child link="1 B_joint_revolute_sim" />
    <origin xyz="0 0 0" rpy="0 0 0" />
    <axis xyz="0 0 1" />
    <limit lower="-1" upper="1" effort="1.0" velocity="1.0" />
  </joint>
  <link name="1 B_joint_revolute_sim">
    <visual>
      <geometry>
        <cylinder length="0.04" radius="0.02" />
      </geometry>
      <material name="black">
        <color rgba="0.0 0.0 0.0 1.0" />
      </material>
    </visual>
    <collision>
      <geometry>
        <cylinder length="0.04" radius="0.02" />
      </geometry>
    </collision>
    <inertial>
      <mass value="0.05" />
      <inertia ixx="7.5e-06" ixy="0.0" ixz="0.0" iyy="7.5e-06" iyz="0.0" izz="7.5e-06" />
    </inertial>
  </link>
  <joint name="joint_13" type="fixed">
    <parent link="1 B_joint_revolute_sim" />
    <child link="Sphere_5" />
    <origin xyz="0 -0.02 0" rpy="0 0 0" />
  </joint>
  <link name="Sphere_5">
    <visual>
      <geometry>
        <sphere radius="0.01" />
      </geometry>
      <material name="black">
        <color rgba="0 0 0 1" />
      </material>
    </visual>
    <collision>
      <geometry>
        <sphere radius="0.01" />
      </geometry>
    </collision>
    <inertial>
      <mass value="0.004" />
      <inertia ixx="1.7e-07" ixy="0.0" ixz="0.0" iyy="1.7e-07" iyz="0.0" izz="1.7e-07" />
    </inertial>
  </link>
  <joint name="joint_14" type="fixed">
    <parent link="Sphere_5" />
    <child link="2 body_Link_CUBE_sim" />
    <origin xyz="0 -0.025 0" rpy="0 0 0" />
  </joint>
  <link name="2 body_Link_CUBE_sim">
    <visual>
      <geometry>
        <box size="0.046 0.046 0.046" />
      </geometry>
      <material name="red">
        <color rgba="1.0 0.0 0.0 1.0" />
      </material>
    </visual>
    <collision>
      <geometry>
        <box size="0.046 0.046 0.046" />
      </geometry>
    </collision>
    <inertial>
      <mass value="0.1" />
      <inertia ixx="0.0000353" ixy="0.0" ixz="0.0" iyy="0.0000353" iyz="0.0" izz="0.0000353" />
    </inertial>
  </link>
</robot>