<?xml version='1.0' encoding='utf-8'?>
<robot name="combined_robot0">
  <link name="1 body_Link_CUBE">
    <visual>
      <geometry>
        <box size="0.1 0.1 0.1" />
      </geometry>
      <material name="red">
        <color rgba="1.0 0.0 0.0 1.0" />
      </material>
    </visual>
    <collision>
      <geometry>
        <box size="0.1 0.1 0.1" />
      </geometry>
    </collision>
    <inertial>
      <mass value="5.0" />
      <inertia ixx="0.025" ixy="0.0" ixz="0.0" iyy="0.025" iyz="0.0" izz="0.025" />
    </inertial>
  </link>
  <joint name="joint_1" type="fixed">
    <parent link="1 body_Link_CUBE" />
    <child link="Sphere_0" />
    <origin xyz="0 -0.05 0" rpy="0 0 0" />
  </joint>
  <link name="Sphere_0">
    <visual>
      <geometry>
        <sphere radius="0.02" />
      </geometry>
      <material name="black">
        <color rgba="0 0 0 1.0" />
      </material>
    </visual>
    <collision>
      <geometry>
        <sphere radius="0.02" />
      </geometry>
    </collision>
    <inertial>
      <mass value="0.5" />
      <inertia ixx="0.0025" ixy="0.0" ixz="0.0" iyy="0.0025" iyz="0.0" izz="0.0025" />
    </inertial>
  </link>
  <joint name="joint_1" type="continuous">
    <parent link="Sphere_0" />
    <child link="2 L_joint_continuous" />
    <origin xyz="0 0 0" rpy="1.55 0 0" />
    <axis xyz="0 0 1" />
  </joint>
  <link name="2 L_joint_continuous">
    <visual>
      <geometry>
        <cylinder length="0.06" radius="0.04" />
      </geometry>
      <material name="black">
        <color rgba="0.0 0.0 0.0 1.0" />
      </material>
    </visual>
    <collision>
      <geometry>
        <cylinder length="0.07" radius="0.03" />
      </geometry>
    </collision>
    <inertial>
      <mass value="0.5" />
      <inertia ixx="0.0025" ixy="0.0" ixz="0.0" iyy="0.0025" iyz="0.0" izz="0.0025" />
    </inertial>
  </link>
  <joint name="joint_2" type="fixed">
    <parent link="2 L_joint_continuous" />
    <child link="blackSphere_0" />
    <origin xyz="0 0 0" rpy="0 0 0" />
  </joint>
  <link name="blackSphere_0">
    <visual>
      <geometry>
        <sphere radius="0.01" />
      </geometry>
      <material name="black">
        <color rgba="0 0 0 55.0" />
      </material>
    </visual>
    <collision>
      <geometry>
        <sphere radius="0.02" />
      </geometry>
    </collision>
    <inertial>
      <mass value="0.5" />
      <inertia ixx="0.0025" ixy="0.0" ixz="0.0" iyy="0.0025" iyz="0.0" izz="0.0025" />
    </inertial>
  </link>
  <joint name="joint_1" type="fixed">
    <parent link="blackSphere_0" />
    <child link="3 limb_Link_Small" />
    <origin xyz="0 0 0.045" rpy="0 0 0" />
  </joint>
  <link name="3 limb_Link_Small">
    <visual>
      <geometry>
        <cylinder length="0.10" radius="0.02125" />
      </geometry>
      <material name="blue">
        <color rgba="0.0 0.0 1.0 1.0" />
      </material>
    </visual>
    <collision>
      <geometry>
        <cylinder length="0.1875" radius="0.02125" />
      </geometry>
    </collision>
    <inertial>
      <mass value="2.5" />
      <inertia ixx="0.0125" ixy="0.0" ixz="0.0" iyy="0.0125" iyz="0.0" izz="0.0125" />
    </inertial>
  </link>
  <joint name="joint_2" type="fixed">
    <parent link="3 limb_Link_Small" />
    <child link="extra_sphere_0" />
    <origin xyz="0 0 0.05" rpy="0 0 0" />
  </joint>
  <link name="extra_sphere_0">
    <visual>
      <geometry>
        <sphere radius="0.02125" />
      </geometry>
      <material name="blue">
        <color rgba="0.0 0.0 1.0 1.0" />
      </material>
    </visual>
    <collision>
      <geometry>
        <sphere radius="0.02125" />
      </geometry>
    </collision>
    <inertial>
      <mass value="2.5" />
      <inertia ixx="0.0125" ixy="0.0" ixz="0.0" iyy="0.0125" iyz="0.0" izz="0.0125" />
    </inertial>
  </link>
  <joint name="joint_1" type="fixed">
    <parent link="1 body_Link_CUBE" />
    <child link="Sphere_1" />
    <origin xyz="0 0.05 0" rpy="0 0 0" />
  </joint>
  <link name="Sphere_1">
    <visual>
      <geometry>
        <sphere radius="0.02" />
      </geometry>
      <material name="black">
        <color rgba="0 0 0 1.0" />
      </material>
    </visual>
    <collision>
      <geometry>
        <sphere radius="0.02" />
      </geometry>
    </collision>
    <inertial>
      <mass value="0.5" />
      <inertia ixx="0.0025" ixy="0.0" ixz="0.0" iyy="0.0025" iyz="0.0" izz="0.0025" />
    </inertial>
  </link>
  <joint name="joint_1" type="fixed">
    <parent link="Sphere_1" />
    <child link="5 L_joint_fixed" />
    <origin xyz="0 0 0" rpy="-1.55 0 0" />
  </joint>
  <link name="5 L_joint_fixed">
    <visual>
      <geometry>
        <box size="0.04 0.04 0.04" />
      </geometry>
      <material name="blue">
        <color rgba="0.0 0.0 0.0 1.0" />
      </material>
    </visual>
    <collision>
      <geometry>
        <box size="0.05 0.05 0.05" />
      </geometry>
    </collision>
    <inertial>
      <mass value="1.0" />
      <inertia ixx="0.002" ixy="0.0" ixz="0.0" iyy="0.002" iyz="0.0" izz="0.003" />
    </inertial>
  </link>
  <joint name="joint_2" type="fixed">
    <parent link="5 L_joint_fixed" />
    <child link="blackSphere_1" />
    <origin xyz="0 0 0" rpy="0 0 0" />
  </joint>
  <link name="blackSphere_1">
    <visual>
      <geometry>
        <cylinder length="0.1" radius="0.01" />
      </geometry>
      <material name="black">
        <color rgba="0.0 0.0 0.0 1.0" />
      </material>
    </visual>
    <collision>
      <geometry>
        <sphere length="0.07" radius="0.05" />
      </geometry>
    </collision>
    <inertial>
      <mass value="0.5" />
      <inertia ixx="0.0025" ixy="0.0" ixz="0.0" iyy="0.0025" iyz="0.0" izz="0.0025" />
    </inertial>
  </link>
  <joint name="joint_1" type="fixed">
    <parent link="blackSphere_1" />
    <child link="6 wheel_link" />
    <origin xyz="0 0 0.04" rpy="0 0 0" />
  </joint>
  <link name="6 wheel_link">
    <visual>
      <geometry>
        <cylinder length="0.025" radius="0.07" />
      </geometry>
      <material name="green">
        <color rgba="0.0 1.0 0.0 1.0" />
      </material>
    </visual>
    <collision>
      <geometry>
        <cylinder length="0.025" radius="0.07" />
      </geometry>
    </collision>
    <inertial>
      <mass value="0.5" />
      <inertia ixx="0.001" ixy="0.0" ixz="0.0" iyy="0.001" iyz="0.0" izz="0.0005" />
    </inertial>
  </link>
  <joint name="joint_1" type="fixed">
    <parent link="1 body_Link_CUBE" />
    <child link="Sphere_2" />
    <origin xyz="-0.05 0 0" rpy="0 0 0" />
  </joint>
  <link name="Sphere_2">
    <visual>
      <geometry>
        <sphere radius="0.02" />
      </geometry>
      <material name="black">
        <color rgba="0 0 0 1.0" />
      </material>
    </visual>
    <collision>
      <geometry>
        <sphere radius="0.02" />
      </geometry>
    </collision>
    <inertial>
      <mass value="0.5" />
      <inertia ixx="0.0025" ixy="0.0" ixz="0.0" iyy="0.0025" iyz="0.0" izz="0.0025" />
    </inertial>
  </link>
  <joint name="joint_1" type="revolute">
    <parent link="Sphere_2" />
    <child link="10 B_joint_revolute" />
    <origin xyz="0 0 0" rpy="0 0 0" />
    <axis xyz="0 0 1" />
    <limit lower="-1" upper="1" effort="1.0" velocity="1.0" />
  </joint>
  <link name="10 B_joint_revolute">
    <visual>
      <geometry>
        <cylinder length="0.07" radius="0.05" />
      </geometry>
      <material name="black">
        <color rgba="0.0 0.0 0.0 1.0" />
      </material>
    </visual>
    <collision>
      <geometry>
        <sphere radius="0.05" />
      </geometry>
    </collision>
    <inertial>
      <mass value="0.5" />
      <inertia ixx="0.0025" ixy="0.0" ixz="0.0" iyy="0.0025" iyz="0.0" izz="0.0025" />
    </inertial>
  </link>
  <joint name="joint_2" type="fixed">
    <parent link="10 B_joint_revolute" />
    <child link="Sphere_3" />
    <origin xyz="-0.05 0 0" rpy="0 0 0" />
  </joint>
  <link name="Sphere_3">
    <visual>
      <geometry>
        <sphere radius="0.02" />
      </geometry>
      <material name="black">
        <color rgba="0 0 0 1" />
      </material>
    </visual>
    <collision>
      <geometry>
        <sphere radius="0.02" />
      </geometry>
    </collision>
    <inertial>
      <mass value="0.5" />
      <inertia ixx="0.0025" ixy="0.0" ixz="0.0" iyy="0.0025" iyz="0.0" izz="0.0025" />
    </inertial>
  </link>
  <joint name="joint_3" type="fixed">
    <parent link="Sphere_3" />
    <child link="11 body_Link_CUBE" />
    <origin xyz="-0.05 0 0" rpy="0 0 0" />
  </joint>
  <link name="11 body_Link_CUBE">
    <visual>
      <geometry>
        <box size="0.1 0.1 0.1" />
      </geometry>
      <material name="red">
        <color rgba="1.0 0.0 0.0 1.0" />
      </material>
    </visual>
    <collision>
      <geometry>
        <box size="0.1 0.1 0.1" />
      </geometry>
    </collision>
    <inertial>
      <mass value="5.0" />
      <inertia ixx="0.025" ixy="0.0" ixz="0.0" iyy="0.025" iyz="0.0" izz="0.025" />
    </inertial>
  </link>
</robot>