<?xml version='1.0' encoding='utf-8'?>
<robot name="combined_robot9">
  <link name="1 body_Link_CUBE">
    <visual>
      <geometry>
        <box size="0.1 0.1 0.1" />
      </geometry>
      <material name="red">
        <color rgba="1.0 0.0 0.0 1.0" />
      </material>
    </visual>
    <collision>
      <geometry>
        <box size="0.1 0.1 0.1" />
      </geometry>
    </collision>
    <inertial>
      <mass value="5.0" />
      <inertia ixx="0.00833" ixy="0.0" ixz="0.0" iyy="0.00833" iyz="0.0" izz="0.00833" />
    </inertial>
  </link>
  <joint name="joint_0" type="fixed">
    <parent link="1 body_Link_CUBE" />
    <child link="Sphere_0" />
    <origin xyz="0 0 -0.05" rpy="0 0 0" />
  </joint>
  <link name="Sphere_0">
    <visual>
      <geometry>
        <sphere radius="0.02" />
      </geometry>
      <material name="black">
        <color rgba="0 0 0 1" />
      </material>
    </visual>
    <collision>
      <geometry>
        <sphere radius="0.02" />
      </geometry>
    </collision>
    <inertial>
      <mass value="0.5" />
      <inertia ixx="0.00008" ixy="0.0" ixz="0.0" iyy="0.00008" iyz="0.0" izz="0.00008" />
    </inertial>
  </link>
  <joint name="joint_1" type="continuous">
    <parent link="Sphere_0" />
    <child link="3 B_joint_continuous" />
    <origin xyz="0 0 0" rpy="0 0 0" />
    <axis xyz="0 0 1" />
    <limit effort="1.0" velocity="1.0" rpy="0 3.15 0" />
  </joint>
  <link name="3 B_joint_continuous">
    <visual>
      <geometry>
        <cylinder length="0.07" radius="0.04" />
      </geometry>
      <material name="black">
        <color rgba="0.0 0.0 0.0 1.0" />
      </material>
    </visual>
    <collision>
      <geometry>
        <cylinder length="0.07" radius="0.04" />
      </geometry>
    </collision>
    <inertial>
      <mass value="0.5" />
      <inertia ixx="0.00040" ixy="0.0" ixz="0.0" iyy="0.00040" iyz="0.0" izz="0.00040" />
    </inertial>
  </link>
  <joint name="joint_2" type="fixed">
    <parent link="3 B_joint_continuous" />
    <child link="4 body_Link_CUBE" />
    <origin xyz="0 0 -0.07" rpy="0 0 0" />
  </joint>
  <link name="4 body_Link_CUBE">
    <visual>
      <geometry>
        <box size="0.1 0.1 0.1" />
      </geometry>
      <material name="red">
        <color rgba="1.0 0.0 0.0 1.0" />
      </material>
    </visual>
    <collision>
      <geometry>
        <box size="0.1 0.1 0.1" />
      </geometry>
    </collision>
    <inertial>
      <mass value="5.0" />
      <inertia ixx="0.00833" ixy="0.0" ixz="0.0" iyy="0.00833" iyz="0.0" izz="0.00833" />
    </inertial>
  </link>
  <joint name="joint_3" type="fixed">
    <parent link="1 body_Link_CUBE" />
    <child link="Sphere_1" />
    <origin xyz="0 0.05 0" rpy="0 0 0" />
  </joint>
  <link name="Sphere_1">
    <visual>
      <geometry>
        <sphere radius="0.02" />
      </geometry>
      <material name="black">
        <color rgba="0 0 0 1.0" />
      </material>
    </visual>
    <collision>
      <geometry>
        <sphere radius="0.02" />
      </geometry>
    </collision>
    <inertial>
      <mass value="0.5" />
      <inertia ixx="0.00008" ixy="0.0" ixz="0.0" iyy="0.00008" iyz="0.0" izz="0.00008" />
    </inertial>
  </link>
  <joint name="joint_4" type="fixed">
    <parent link="Sphere_1" />
    <child link="12 B_joint_fixed" />
    <origin xyz="0 0 0" rpy="0 0 0" />
  </joint>
  <link name="12 B_joint_fixed">
    <visual>
      <geometry>
        <box size="0.07 0.07 0.07" />
      </geometry>
      <material name="black">
        <color rgba="0.0 0.0 0.0 1.0" />
      </material>
    </visual>
    <collision>
      <geometry>
        <box size="0.07 0.07 0.07" />
      </geometry>
    </collision>
    <inertial>
      <mass value="1.0" />
      <inertia ixx="0.00082" ixy="0.0" ixz="0.0" iyy="0.00082" iyz="0.0" izz="0.00082" />
    </inertial>
  </link>
  <joint name="joint_5" type="fixed">
    <parent link="12 B_joint_fixed" />
    <child link="13 body_Link_CUBE" />
    <origin xyz="0 0.07 0" rpy="0 0 0" />
  </joint>
  <link name="13 body_Link_CUBE">
    <visual>
      <geometry>
        <box size="0.1 0.1 0.1" />
      </geometry>
      <material name="red">
        <color rgba="1.0 0.0 0.0 1.0" />
      </material>
    </visual>
    <collision>
      <geometry>
        <box size="0.1 0.1 0.1" />
      </geometry>
    </collision>
    <inertial>
      <mass value="5.0" />
      <inertia ixx="0.00833" ixy="0.0" ixz="0.0" iyy="0.00833" iyz="0.0" izz="0.00833" />
    </inertial>
  </link>
</robot>