<?xml version='1.0' encoding='utf-8'?>
<robot name="combined_robot8">
  <link name="1 body_Link_CUBE">
    <visual>
      <geometry>
        <box size="0.1 0.1 0.1" />
      </geometry>
      <material name="red">
        <color rgba="1.0 0.0 0.0 1.0" />
      </material>
    </visual>
    <collision>
      <geometry>
        <box size="0.1 0.1 0.1" />
      </geometry>
    </collision>
    <inertial>
      <mass value="5.0" />
      <inertia ixx="0.00833" ixy="0.0" ixz="0.0" iyy="0.00833" iyz="0.0" izz="0.00833" />
    </inertial>
  </link>
  <joint name="joint_0" type="fixed">
    <parent link="1 body_Link_CUBE" />
    <child link="Sphere_0" />
    <origin xyz="0 -0.05 0" rpy="0 0 0" />
  </joint>
  <link name="Sphere_0">
    <visual>
      <geometry>
        <sphere radius="0.02" />
      </geometry>
      <material name="black">
        <color rgba="0 0 0 1.0" />
      </material>
    </visual>
    <collision>
      <geometry>
        <sphere radius="0.02" />
      </geometry>
    </collision>
    <inertial>
      <mass value="0.5" />
      <inertia ixx="0.00008" ixy="0.0" ixz="0.0" iyy="0.00008" iyz="0.0" izz="0.00008" />
    </inertial>
  </link>
  <joint name="joint_1" type="fixed">
    <parent link="Sphere_0" />
    <child link="2 B_joint_fixed" />
    <origin xyz="0 0 0" rpy="0 0 0" />
  </joint>
  <link name="2 B_joint_fixed">
    <visual>
      <geometry>
        <box size="0.07 0.07 0.07" />
      </geometry>
      <material name="black">
        <color rgba="0.0 0.0 0.0 1.0" />
      </material>
    </visual>
    <collision>
      <geometry>
        <box size="0.07 0.07 0.07" />
      </geometry>
    </collision>
    <inertial>
      <mass value="1.0" />
      <inertia ixx="0.00082" ixy="0.0" ixz="0.0" iyy="0.00082" iyz="0.0" izz="0.00082" />
    </inertial>
  </link>
  <joint name="joint_2" type="fixed">
    <parent link="2 B_joint_fixed" />
    <child link="3 body_Link_CUBE" />
    <origin xyz="0 -0.07 0" rpy="0 0 0" />
  </joint>
  <link name="3 body_Link_CUBE">
    <visual>
      <geometry>
        <box size="0.1 0.1 0.1" />
      </geometry>
      <material name="red">
        <color rgba="1.0 0.0 0.0 1.0" />
      </material>
    </visual>
    <collision>
      <geometry>
        <box size="0.1 0.1 0.1" />
      </geometry>
    </collision>
    <inertial>
      <mass value="5.0" />
      <inertia ixx="0.00833" ixy="0.0" ixz="0.0" iyy="0.00833" iyz="0.0" izz="0.00833" />
    </inertial>
  </link>
  <joint name="joint_3" type="fixed">
    <parent link="1 body_Link_CUBE" />
    <child link="Sphere_1" />
    <origin xyz="0.05 0 0" rpy="0 0 0" />
  </joint>
  <link name="Sphere_1">
    <visual>
      <geometry>
        <sphere radius="0.02" />
      </geometry>
      <material name="black">
        <color rgba="0 0 0 1.0" />
      </material>
    </visual>
    <collision>
      <geometry>
        <sphere radius="0.02" />
      </geometry>
    </collision>
    <inertial>
      <mass value="0.5" />
      <inertia ixx="0.00008" ixy="0.0" ixz="0.0" iyy="0.00008" iyz="0.0" izz="0.00008" />
    </inertial>
  </link>
  <joint name="joint_4" type="continuous">
    <parent link="Sphere_1" />
    <child link="10 L_joint_continuous" />
    <origin xyz="0 0 0" rpy="0 1.55 0" />
    <axis xyz="0 0 1" rpy="0 1.55 0" />
    <limit effort="1.0" velocity="1.0" rpy="0 1.55 0" />
  </joint>
  <link name="10 L_joint_continuous">
    <visual>
      <geometry>
        <cylinder length="0.06" radius="0.04" />
      </geometry>
      <material name="black">
        <color rgba="0.0 0.0 0.0 1.0" />
      </material>
    </visual>
    <collision>
      <geometry>
        <cylinder length="0.06" radius="0.04" />
      </geometry>
    </collision>
    <inertial>
      <mass value="0.5" />
      <inertia ixx="0.00035" ixy="0.0" ixz="0.0" iyy="0.00035" iyz="0.0" izz="0.00040" />
    </inertial>
  </link>
  <joint name="joint_5" type="fixed">
    <parent link="10 L_joint_continuous" />
    <child link="blackSphere_0" />
    <origin xyz="0 0 0" rpy="0 0 0" />
  </joint>
  <link name="blackSphere_0">
    <visual>
      <geometry>
        <sphere radius="0.01" />
      </geometry>
      <material name="black">
        <color rgba="0 0 0 55.0" />
      </material>
    </visual>
    <collision>
      <geometry>
        <sphere radius="0.01" />
      </geometry>
    </collision>
    <inertial>
      <mass value="0.5" />
      <inertia ixx="0.00016" ixy="0.0" ixz="0.0" iyy="0.00016" iyz="0.0" izz="0.00016" />
    </inertial>
  </link>
  <joint name="joint_6" type="fixed">
    <parent link="blackSphere_0" />
    <child link="11 limb_Link_Small" />
    <origin xyz="0 0 0.045" rpy="0 0 3.15" />
  </joint>
  <link name="11 limb_Link_Small">
    <visual>
      <geometry>
        <cylinder length="0.10" radius="0.03" />
      </geometry>
      <material name="blue">
        <color rgba="0.0 0.0 0.8 1.0" />
      </material>
    </visual>
    <collision>
      <geometry>
        <cylinder length="0.10" radius="0.02125" />
      </geometry>
    </collision>
    <inertial>
      <mass value="2.5" />
      <inertia ixx="0.00761" ixy="0.0" ixz="0.0" iyy="0.00761" iyz="0.0" izz="0.00056" />
    </inertial>
  </link>
  <joint name="joint_7" type="fixed">
    <parent link="11 limb_Link_Small" />
    <child link="extra_sphere_1" />
    <origin xyz="0 0 0.05" rpy="0 0 0" />
  </joint>
  <link name="extra_sphere_1">
    <visual>
      <geometry>
        <sphere radius="0.03" />
      </geometry>
      <material name="blue">
        <color rgba="0.0 0.0 0.8 1.0" />
      </material>
    </visual>
    <collision>
      <geometry>
        <sphere radius="0.02125" />
      </geometry>
    </collision>
    <inertial>
      <mass value="2.5" />
      <inertia ixx="0.00045" ixy="0.0" ixz="0.0" iyy="0.00045" iyz="0.0" izz="0.00045" />
    </inertial>
  </link>
  <joint name="joint_8" type="fixed">
    <parent link="1 body_Link_CUBE" />
    <child link="Sphere_2" />
    <origin xyz="0 0 0.05" rpy="0 0 0" />
  </joint>
  <link name="Sphere_2">
    <visual>
      <geometry>
        <sphere radius="0.02" />
      </geometry>
      <material name="black">
        <color rgba="0 0 0 1.0" />
      </material>
    </visual>
    <collision>
      <geometry>
        <sphere radius="0.02" />
      </geometry>
    </collision>
    <inertial>
      <mass value="0.5" />
      <inertia ixx="0.00008" ixy="0.0" ixz="0.0" iyy="0.00008" iyz="0.0" izz="0.00008" />
    </inertial>
  </link>
  <joint name="joint_9" type="continuous">
    <parent link="Sphere_2" />
    <child link="14 L_joint_continuous" />
    <origin xyz="0 0 0" rpy="0 0 0" />
    <axis xyz="0 0 1" />
    <limit effort="1.0" velocity="1.0" rpy="0 3.15 0" />
  </joint>
  <link name="14 L_joint_continuous">
    <visual>
      <geometry>
        <cylinder length="0.06" radius="0.04" />
      </geometry>
      <material name="black">
        <color rgba="0.0 0.0 0.0 1.0" />
      </material>
    </visual>
    <collision>
      <geometry>
        <cylinder length="0.06" radius="0.04" />
      </geometry>
    </collision>
    <inertial>
      <mass value="0.5" />
      <inertia ixx="0.00035" ixy="0.0" ixz="0.0" iyy="0.00035" iyz="0.0" izz="0.00040" />
    </inertial>
  </link>
  <joint name="joint_10" type="fixed">
    <parent link="14 L_joint_continuous" />
    <child link="blackSphere_1" />
    <origin xyz="0 0 0" rpy="0 0 0" />
  </joint>
  <link name="blackSphere_1">
    <visual>
      <geometry>
        <sphere radius="0.01" />
      </geometry>
      <material name="black">
        <color rgba="0 0 0 55.0" />
      </material>
    </visual>
    <collision>
      <geometry>
        <sphere radius="0.01" />
      </geometry>
    </collision>
    <inertial>
      <mass value="0.5" />
      <inertia ixx="0.00016" ixy="0.0" ixz="0.0" iyy="0.00016" iyz="0.0" izz="0.00016" />
    </inertial>
  </link>
  <joint name="joint_11" type="fixed">
    <parent link="blackSphere_1" />
    <child link="15 limb_Link_Small" />
    <origin xyz="0 0 0.045" rpy="0 0 3.15" />
  </joint>
  <link name="15 limb_Link_Small">
    <visual>
      <geometry>
        <cylinder length="0.10" radius="0.03" />
      </geometry>
      <material name="blue">
        <color rgba="0.0 0.0 0.8 1.0" />
      </material>
    </visual>
    <collision>
      <geometry>
        <cylinder length="0.10" radius="0.02125" />
      </geometry>
    </collision>
    <inertial>
      <mass value="2.5" />
      <inertia ixx="0.00761" ixy="0.0" ixz="0.0" iyy="0.00761" iyz="0.0" izz="0.00056" />
    </inertial>
  </link>
  <joint name="joint_12" type="fixed">
    <parent link="15 limb_Link_Small" />
    <child link="extra_sphere_2" />
    <origin xyz="0 0 0.05" rpy="0 0 0" />
  </joint>
  <link name="extra_sphere_2">
    <visual>
      <geometry>
        <sphere radius="0.03" />
      </geometry>
      <material name="blue">
        <color rgba="0.0 0.0 0.8 1.0" />
      </material>
    </visual>
    <collision>
      <geometry>
        <sphere radius="0.02125" />
      </geometry>
    </collision>
    <inertial>
      <mass value="2.5" />
      <inertia ixx="0.00045" ixy="0.0" ixz="0.0" iyy="0.00045" iyz="0.0" izz="0.00045" />
    </inertial>
  </link>
</robot>