<?xml version='1.0' encoding='utf-8'?>
<robot name="combined_robot0">
  <link name="1 body_Link_CUBE">
    <visual>
      <geometry>
        <box size="0.1 0.1 0.1" />
      </geometry>
      <material name="red">
        <color rgba="1.0 0.0 0.0 1.0" />
      </material>
    </visual>
    <collision>
      <geometry>
        <box size="0.1 0.1 0.1" />
      </geometry>
    </collision>
    <inertial>
      <mass value="5.0" />
      <inertia ixx="0.00833" ixy="0.0" ixz="0.0" iyy="0.00833" iyz="0.0" izz="0.00833" />
    </inertial>
  </link>
  <joint name="joint_0" type="fixed">
    <parent link="1 body_Link_CUBE" />
    <child link="Sphere_0" />
    <origin xyz="0.05 0 0" rpy="0 0 0" />
  </joint>
  <link name="Sphere_0">
    <visual>
      <geometry>
        <sphere radius="0.02" />
      </geometry>
      <material name="black">
        <color rgba="0 0 0 1.0" />
      </material>
    </visual>
    <collision>
      <geometry>
        <sphere radius="0.02" />
      </geometry>
    </collision>
    <inertial>
      <mass value="0.5" />
      <inertia ixx="0.00008" ixy="0.0" ixz="0.0" iyy="0.00008" iyz="0.0" izz="0.00008" />
    </inertial>
  </link>
  <joint name="joint_1" type="fixed">
    <parent link="Sphere_0" />
    <child link="2 L_joint_fixed" />
    <origin xyz="0 0 0" rpy="0 1.55 0" />
  </joint>
  <link name="2 L_joint_fixed">
    <visual>
      <geometry>
        <box size="0.04 0.04 0.04" />
      </geometry>
      <material name="blue">
        <color rgba="0.0 0.0 0.0 1.0" />
      </material>
    </visual>
    <collision>
      <geometry>
        <box size="0.04 0.04 0.04" />
      </geometry>
    </collision>
    <inertial>
      <mass value="1.0" />
      <inertia ixx="0.00027" ixy="0.0" ixz="0.0" iyy="0.00027" iyz="0.0" izz="0.00027" />
    </inertial>
  </link>
  <joint name="joint_2" type="fixed">
    <parent link="2 L_joint_fixed" />
    <child link="blackSphere_0" />
    <origin xyz="0 0 0" rpy="0 0 0" />
  </joint>
  <link name="blackSphere_0">
    <visual>
      <geometry>
        <sphere radius="0.02" />
      </geometry>
      <material name="black">
        <color rgba="0 0 0 55.0" />
      </material>
    </visual>
    <collision>
      <geometry>
        <sphere radius="0.02" />
      </geometry>
    </collision>
    <inertial>
      <mass value="0.5" />
      <inertia ixx="0.00008" ixy="0.0" ixz="0.0" iyy="0.00008" iyz="0.0" izz="0.00008" />
    </inertial>
  </link>
  <joint name="joint_3" type="fixed">
    <parent link="blackSphere_0" />
    <child link="3 limb_Link" />
    <origin xyz="0 0 0.09" rpy="0 0 3.15" />
  </joint>
  <link name="3 limb_Link">
    <visual>
      <geometry>
        <cylinder length="0.1875" radius="0.03125" />
      </geometry>
      <material name="blue">
        <color rgba="0.0 0.0 1.0 1.0" />
      </material>
    </visual>
    <visual>
      <origin xyz="0.03125 0 0" rpy="0 0 0" />
      <geometry>
        <box size="0.003 0.003 0.1875" />
      </geometry>
      <material name="red_line">
        <color rgba="1.0 0.0 0.0 1.0" />
      </material>
    </visual>
    <collision>
      <geometry>
        <cylinder length="0.1875" radius="0.03125" />
      </geometry>
    </collision>
    <inertial>
      <mass value="2.5" />
      <inertia ixx="0.00794" ixy="0.0" ixz="0.0" iyy="0.00794" iyz="0.0" izz="0.00122" />
    </inertial>
  </link>
  <joint name="joint_4" type="fixed">
    <parent link="3 limb_Link" />
    <child link="extra_sphere_1" />
    <origin xyz="0 0 0.09" rpy="0 0 0" />
  </joint>
  <link name="extra_sphere_1">
    <visual>
      <geometry>
        <sphere radius="0.03125" />
      </geometry>
      <material name="blue">
        <color rgba="0.0 0.0 1.0 1.0" />
      </material>
    </visual>
    <collision>
      <geometry>
        <sphere radius="0.03125" />
      </geometry>
    </collision>
    <inertial>
      <mass value="2.5" />
      <inertia ixx="0.00098" ixy="0.0" ixz="0.0" iyy="0.00098" iyz="0.0" izz="0.00098" />
    </inertial>
  </link>
  <joint name="joint_5" type="revolute">
    <parent link="extra_sphere_1" />
    <child link="4 L_joint_continuous" />
    <origin xyz="0 0 0" rpy="0 0 0" />
    <axis xyz="0 0 1" />
    <limit lower="-1000" upper="1000" effort="1.0" velocity="1.0" rpy="0 3.15 0" />
  </joint>
  <link name="4 L_joint_continuous">
    <visual>
      <geometry>
        <cylinder length="0.06" radius="0.04" />
      </geometry>
      <material name="black">
        <color rgba="0.0 0.0 0.0 1.0" />
      </material>
    </visual>
    <collision>
      <geometry>
        <cylinder length="0.06" radius="0.04" />
      </geometry>
    </collision>
    <inertial>
      <mass value="0.5" />
      <inertia ixx="0.00035" ixy="0.0" ixz="0.0" iyy="0.00035" iyz="0.0" izz="0.00040" />
    </inertial>
  </link>
  <joint name="joint_6" type="fixed">
    <parent link="4 L_joint_continuous" />
    <child link="blackSphere_1" />
    <origin xyz="0 0 0" rpy="0 0 0" />
  </joint>
  <link name="blackSphere_1">
    <visual>
      <geometry>
        <cylinder length="0.1" radius="0.01" />
      </geometry>
      <material name="black">
        <color rgba="0.0 0.0 0.0 1.0" />
      </material>
    </visual>
    <collision>
      <geometry>
        <sphere length="0.07" radius="0.05" />
      </geometry>
    </collision>
    <inertial>
      <mass value="0.5" />
      <inertia ixx="0.0025" ixy="0.0" ixz="0.0" iyy="0.0025" iyz="0.0" izz="0.0025" />
    </inertial>
  </link>
  <joint name="joint_7" type="fixed">
    <parent link="blackSphere_1" />
    <child link="5 wheel_link" />
    <origin xyz="0 0 0.04" rpy="0 0 0" />
  </joint>
  <link name="5 wheel_link">
    <visual>
      <geometry>
        <cylinder length="0.025" radius="0.07" />
      </geometry>
      <material name="green">
        <color rgba="0.0 1.0 0.0 1.0" />
      </material>
    </visual>
    <visual>
      <origin xyz="0 0 0.011" rpy="0 0 0" />
      <geometry>
        <box size="0.14 0.004 0.004" />
      </geometry>
      <material name="red_line">
        <color rgba="1.0 0.0 0.0 1.0" />
      </material>
    </visual>
    <collision>
      <geometry>
        <cylinder length="0.025" radius="0.07" />
      </geometry>
    </collision>
    <inertial>
      <mass value="0.5" />
      <inertia ixx="0.001" ixy="0.0" ixz="0.0" iyy="0.001" iyz="0.0" izz="0.0005" />
    </inertial>
  </link>
  <joint name="joint_8" type="fixed">
    <parent link="1 body_Link_CUBE" />
    <child link="Sphere_1" />
    <origin xyz="0 0.05 0" rpy="0 0 0" />
  </joint>
  <link name="Sphere_1">
    <visual>
      <geometry>
        <sphere radius="0.02" />
      </geometry>
      <material name="black">
        <color rgba="0 0 0 1.0" />
      </material>
    </visual>
    <collision>
      <geometry>
        <sphere radius="0.02" />
      </geometry>
    </collision>
    <inertial>
      <mass value="0.5" />
      <inertia ixx="0.00008" ixy="0.0" ixz="0.0" iyy="0.00008" iyz="0.0" izz="0.00008" />
    </inertial>
  </link>
  <joint name="joint_9" type="fixed">
    <parent link="Sphere_1" />
    <child link="7 B_joint_fixed" />
    <origin xyz="0 0 0" rpy="0 0 0" />
  </joint>
  <link name="7 B_joint_fixed">
    <visual>
      <geometry>
        <box size="0.07 0.07 0.07" />
      </geometry>
      <material name="blue">
        <color rgba="0.0 0.0 0.0 1.0" />
      </material>
    </visual>
    <collision>
      <geometry>
        <box size="0.07 0.07 0.07" />
      </geometry>
    </collision>
    <inertial>
      <mass value="1.0" />
      <inertia ixx="0.00082" ixy="0.0" ixz="0.0" iyy="0.00082" iyz="0.0" izz="0.00082" />
    </inertial>
  </link>
  <joint name="joint_10" type="fixed">
    <parent link="7 B_joint_fixed" />
    <child link="8 body_Link_CUBE" />
    <origin xyz="0 0.07 0" rpy="0 0 0" />
  </joint>
  <link name="8 body_Link_CUBE">
    <visual>
      <geometry>
        <box size="0.1 0.1 0.1" />
      </geometry>
      <material name="red">
        <color rgba="1.0 0.0 0.0 1.0" />
      </material>
    </visual>
    <collision>
      <geometry>
        <box size="0.1 0.1 0.1" />
      </geometry>
    </collision>
    <inertial>
      <mass value="5.0" />
      <inertia ixx="0.00833" ixy="0.0" ixz="0.0" iyy="0.00833" iyz="0.0" izz="0.00833" />
    </inertial>
  </link>
  <joint name="joint_11" type="fixed">
    <parent link="1 body_Link_CUBE" />
    <child link="Sphere_2" />
    <origin xyz="0 0 -0.05" rpy="0 0 0" />
  </joint>
  <link name="Sphere_2">
    <visual>
      <geometry>
        <sphere radius="0.02" />
      </geometry>
      <material name="black">
        <color rgba="0 0 0 1" />
      </material>
    </visual>
    <collision>
      <geometry>
        <sphere radius="0.02" />
      </geometry>
    </collision>
    <inertial>
      <mass value="0.5" />
      <inertia ixx="0.00008" ixy="0.0" ixz="0.0" iyy="0.00008" iyz="0.0" izz="0.00008" />
    </inertial>
  </link>
  <joint name="joint_12" type="revolute">
    <parent link="Sphere_2" />
    <child link="16 L_joint_revolute" />
    <origin xyz="0 0 0" rpy="0 -1.55 0" />
    <axis xyz="0 0 1" rpy="0 3.15 0" />
    <limit lower="-0.75" upper="0.75" effort="1.0" velocity="1.0" rpy="0 3.15 0" />
  </joint>
  <link name="16 L_joint_revolute">
    <visual>
      <geometry>
        <cylinder length="0.065" radius="0.04" />
      </geometry>
      <material name="black">
        <color rgba="0.0 0.0 0.0 1.0" />
      </material>
    </visual>
    <collision>
      <geometry>
        <cylinder length="0.065" radius="0.04" />
      </geometry>
    </collision>
    <inertial>
      <mass value="0.5" />
      <inertia ixx="0.00038" ixy="0.0" ixz="0.0" iyy="0.00038" iyz="0.0" izz="0.0004" />
    </inertial>
  </link>
  <joint name="joint_13" type="fixed">
    <parent link="16 L_joint_revolute" />
    <child link="blackSphere_2" />
    <origin xyz="0 0 0" rpy="0 -1.6 0" />
  </joint>
  <link name="blackSphere_2">
    <visual>
      <geometry>
        <cylinder length="0.1" radius="0.01" />
      </geometry>
      <material name="black">
        <color rgba="0.0 0.0 0.0 1.0" />
      </material>
    </visual>
    <collision>
      <geometry>
        <sphere length="0.07" radius="0.05" />
      </geometry>
    </collision>
    <inertial>
      <mass value="0.5" />
      <inertia ixx="0.0025" ixy="0.0" ixz="0.0" iyy="0.0025" iyz="0.0" izz="0.0025" />
    </inertial>
  </link>
  <joint name="joint_14" type="fixed">
    <parent link="blackSphere_2" />
    <child link="17 wheel_link" />
    <origin xyz="0 0 0.04" rpy="0 0 0" />
  </joint>
  <link name="17 wheel_link">
    <visual>
      <geometry>
        <cylinder length="0.025" radius="0.07" />
      </geometry>
      <material name="green">
        <color rgba="0.0 1.0 0.0 1.0" />
      </material>
    </visual>
    <visual>
      <origin xyz="0 0 0.011" rpy="0 0 0" />
      <geometry>
        <box size="0.14 0.004 0.004" />
      </geometry>
      <material name="red_line">
        <color rgba="1.0 0.0 0.0 1.0" />
      </material>
    </visual>
    <collision>
      <geometry>
        <cylinder length="0.025" radius="0.07" />
      </geometry>
    </collision>
    <inertial>
      <mass value="0.5" />
      <inertia ixx="0.001" ixy="0.0" ixz="0.0" iyy="0.001" iyz="0.0" izz="0.0005" />
    </inertial>
  </link>
</robot>