<?xml version='1.0' encoding='utf-8'?>
<robot name="combined_robot_GEN_0_number_37">
  <link name="0 body_Link_CUBE">
    <visual>
      <geometry>
        <box size="0.046 0.046 0.046" />
      </geometry>
      <material name="red">
        <color rgba="1.0 0.0 0.0 1.0" />
      </material>
    </visual>
    <collision>
      <geometry>
        <box size="0.046 0.046 0.046" />
      </geometry>
    </collision>
    <inertial>
      <mass value="0.1" />
      <inertia ixx="0.0000353" ixy="0.0" ixz="0.0" iyy="0.0000353" iyz="0.0" izz="0.0000353" />
    </inertial>
  </link>
  <joint name="joint_0" type="fixed">
    <parent link="0 body_Link_CUBE" />
    <child link="Sphere_0" />
    <origin xyz="0 0 -0.023" rpy="0 0 0" />
  </joint>
  <link name="Sphere_0">
    <visual>
      <geometry>
        <sphere radius="0.01" />
      </geometry>
      <material name="black">
        <color rgba="0 0 0 1" />
      </material>
    </visual>
    <collision>
      <geometry>
        <sphere radius="0.01" />
      </geometry>
    </collision>
    <inertial>
      <mass value="0.004" />
      <inertia ixx="1.7e-07" ixy="0.0" ixz="0.0" iyy="1.7e-07" iyz="0.0" izz="1.7e-07" />
    </inertial>
  </link>
  <joint name="joint_1" type="continuous">
    <parent link="Sphere_0" />
    <child link="1 B_joint_continuous" />
    <origin xyz="0 0 0" rpy="0 0 0" />
    <axis xyz="0 0 1" />
    <limit effort="1.0" velocity="1.0" rpy="0 3.15 0" />
  </joint>
  <link name="1 B_joint_continuous">
    <visual>
      <geometry>
        <cylinder length="0.04" radius="0.02" />
      </geometry>
      <material name="black">
        <color rgba="0.0 0.0 0.0 1.0" />
      </material>
    </visual>
    <collision>
      <geometry>
        <cylinder length="0.04" radius="0.02" />
      </geometry>
    </collision>
    <inertial>
      <mass value="0.05" />
      <inertia ixx="7.5e-06" ixy="0.0" ixz="0.0" iyy="7.5e-06" iyz="0.0" izz="7.5e-06" />
    </inertial>
  </link>
  <joint name="joint_2" type="fixed">
    <parent link="1 B_joint_continuous" />
    <child link="2 body_Link_CUBE" />
    <origin xyz="0 0 -0.035" rpy="0 0 0" />
  </joint>
  <link name="2 body_Link_CUBE">
    <visual>
      <geometry>
        <box size="0.046 0.046 0.046" />
      </geometry>
      <material name="red">
        <color rgba="1.0 0.0 0.0 1.0" />
      </material>
    </visual>
    <collision>
      <geometry>
        <box size="0.046 0.046 0.046" />
      </geometry>
    </collision>
    <inertial>
      <mass value="0.1" />
      <inertia ixx="0.0000353" ixy="0.0" ixz="0.0" iyy="0.0000353" iyz="0.0" izz="0.0000353" />
    </inertial>
  </link>
  <joint name="joint_3" type="fixed">
    <parent link="2 body_Link_CUBE" />
    <child link="Sphere_1" />
    <origin xyz="-0.023 0 0" rpy="0 0 0" />
  </joint>
  <link name="Sphere_1">
    <visual>
      <geometry>
        <sphere radius="0.01" />
      </geometry>
      <material name="black">
        <color rgba="0 0 0 1.0" />
      </material>
    </visual>
    <collision>
      <geometry>
        <sphere radius="0.01" />
      </geometry>
    </collision>
    <inertial>
      <mass value="0.004" />
      <inertia ixx="1.7e-07" ixy="0.0" ixz="0.0" iyy="1.7e-07" iyz="0.0" izz="1.7e-07" />
    </inertial>
  </link>
  <joint name="joint_4" type="fixed">
    <parent link="Sphere_1" />
    <child link="3 B_joint_fixed" />
    <origin xyz="0 0 0" rpy="0 0 0" />
  </joint>
  <link name="3 B_joint_fixed">
    <visual>
      <geometry>
        <box size="0.03 0.03 0.03" />
      </geometry>
      <material name="black">
        <color rgba="0.0 0.0 0.0 1.0" />
      </material>
    </visual>
    <collision>
      <geometry>
        <box size="0.03 0.03 0.03" />
      </geometry>
    </collision>
    <inertial>
      <mass value="0.05" />
      <inertia ixx="7.5e-06" ixy="0.0" ixz="0.0" iyy="7.5e-06" iyz="0.0" izz="7.5e-06" />
    </inertial>
  </link>
  <joint name="joint_5" type="fixed">
    <parent link="3 B_joint_fixed" />
    <child link="4 body_Link_CUBE" />
    <origin xyz="-0.03 0 0" rpy="0 0 0" />
  </joint>
  <link name="4 body_Link_CUBE">
    <visual>
      <geometry>
        <box size="0.046 0.046 0.046" />
      </geometry>
      <material name="red">
        <color rgba="1.0 0.0 0.0 1.0" />
      </material>
    </visual>
    <collision>
      <geometry>
        <box size="0.046 0.046 0.046" />
      </geometry>
    </collision>
    <inertial>
      <mass value="0.1" />
      <inertia ixx="0.0000353" ixy="0.0" ixz="0.0" iyy="0.0000353" iyz="0.0" izz="0.0000353" />
    </inertial>
  </link>
  <joint name="joint_6" type="fixed">
    <parent link="2 body_Link_CUBE" />
    <child link="Sphere_2" />
    <origin xyz="0 0 -0.023" rpy="0 0 0" />
  </joint>
  <link name="Sphere_2">
    <visual>
      <geometry>
        <sphere radius="0.01" />
      </geometry>
      <material name="black">
        <color rgba="0 0 0 1" />
      </material>
    </visual>
    <collision>
      <geometry>
        <sphere radius="0.01" />
      </geometry>
    </collision>
    <inertial>
      <mass value="0.004" />
      <inertia ixx="1.7e-07" ixy="0.0" ixz="0.0" iyy="1.7e-07" iyz="0.0" izz="1.7e-07" />
    </inertial>
  </link>
  <joint name="joint_7" type="fixed">
    <parent link="Sphere_2" />
    <child link="11 L_joint_fixed" />
    <origin xyz="0 0 0" rpy="0 3.15 0" />
  </joint>
  <link name="11 L_joint_fixed">
    <visual>
      <geometry>
        <box size="0.03 0.03 0.03" />
      </geometry>
      <material name="black">
        <color rgba="0.0 0.0 0.0 1.0" />
      </material>
    </visual>
    <collision>
      <geometry>
        <box size="0.03 0.03 0.03" />
      </geometry>
    </collision>
    <inertial>
      <mass value="0.05" />
      <inertia ixx="7.5e-06" ixy="0.0" ixz="0.0" iyy="7.5e-06" iyz="0.0" izz="7.5e-06" />
    </inertial>
  </link>
  <joint name="joint_8" type="fixed">
    <parent link="11 L_joint_fixed" />
    <child link="blackSphere_0" />
    <origin xyz="0 0 0.01" rpy="0 0 0" />
  </joint>
  <link name="blackSphere_0">
    <visual>
      <geometry>
        <cylinder length="0.04" radius="0.009" />
      </geometry>
      <material name="black">
        <color rgba="0.0 0.0 0.0 1.0" />
      </material>
    </visual>
    <collision>
      <geometry>
        <cylinder length="0.04" radius="0.009" />
      </geometry>
    </collision>
    <inertial>
      <mass value="0.065" />
      <inertia ixx="0.0025" ixy="0.0" ixz="0.0" iyy="0.0025" iyz="0.0" izz="0.0025" />
    </inertial>
  </link>
  <joint name="joint_9" type="fixed">
    <parent link="blackSphere_0" />
    <child link="12 wheel_link" />
    <origin xyz="0 0 0.02" rpy="0 0 0" />
  </joint>
  <link name="12 wheel_link">
    <visual>
      <geometry>
        <cylinder length="0.012" radius="0.033" />
      </geometry>
      <material name="green">
        <color rgba="0.0 1.0 0.0 1.0" />
      </material>
    </visual>
    <collision>
      <geometry>
        <cylinder length="0.012" radius="0.033" />
      </geometry>
    </collision>
    <inertial>
      <mass value="0.065" />
      <inertia ixx="0.00001848" ixy="0.0" ixz="0.0" iyy="0.00001848" iyz="0.0" izz="0.00003539" />
    </inertial>
  </link>
  <joint name="joint_10" type="fixed">
    <parent link="0 body_Link_CUBE" />
    <child link="Sphere_3" />
    <origin xyz="0 0.023 0" rpy="0 0 0" />
  </joint>
  <link name="Sphere_3">
    <visual>
      <geometry>
        <sphere radius="0.01" />
      </geometry>
      <material name="black">
        <color rgba="0 0 0 1.0" />
      </material>
    </visual>
    <collision>
      <geometry>
        <sphere radius="0.01" />
      </geometry>
    </collision>
    <inertial>
      <mass value="0.004" />
      <inertia ixx="1.7e-07" ixy="0.0" ixz="0.0" iyy="1.7e-07" iyz="0.0" izz="1.7e-07" />
    </inertial>
  </link>
  <joint name="joint_11" type="fixed">
    <parent link="Sphere_3" />
    <child link="16 B_joint_fixed" />
    <origin xyz="0 0 0" rpy="0 0 0" />
  </joint>
  <link name="16 B_joint_fixed">
    <visual>
      <geometry>
        <box size="0.03 0.03 0.03" />
      </geometry>
      <material name="black">
        <color rgba="0.0 0.0 0.0 1.0" />
      </material>
    </visual>
    <collision>
      <geometry>
        <box size="0.03 0.03 0.03" />
      </geometry>
    </collision>
    <inertial>
      <mass value="0.05" />
      <inertia ixx="7.5e-06" ixy="0.0" ixz="0.0" iyy="7.5e-06" iyz="0.0" izz="7.5e-06" />
    </inertial>
  </link>
  <joint name="joint_12" type="fixed">
    <parent link="16 B_joint_fixed" />
    <child link="17 body_Link_CUBE" />
    <origin xyz="0 0.03 0" rpy="0 0 0" />
  </joint>
  <link name="17 body_Link_CUBE">
    <visual>
      <geometry>
        <box size="0.046 0.046 0.046" />
      </geometry>
      <material name="red">
        <color rgba="1.0 0.0 0.0 1.0" />
      </material>
    </visual>
    <collision>
      <geometry>
        <box size="0.046 0.046 0.046" />
      </geometry>
    </collision>
    <inertial>
      <mass value="0.1" />
      <inertia ixx="0.0000353" ixy="0.0" ixz="0.0" iyy="0.0000353" iyz="0.0" izz="0.0000353" />
    </inertial>
  </link>
  <joint name="joint_16" type="fixed">
    <parent link="17 body_Link_CUBE" />
    <child link="Sphere_5" />
    <origin xyz="-0.023 0 0" rpy="0 0 0" />
  </joint>
  <link name="Sphere_5">
    <visual>
      <geometry>
        <sphere radius="0.01" />
      </geometry>
      <material name="black">
        <color rgba="0 0 0 1.0" />
      </material>
    </visual>
    <collision>
      <geometry>
        <sphere radius="0.01" />
      </geometry>
    </collision>
    <inertial>
      <mass value="0.004" />
      <inertia ixx="1.7e-07" ixy="0.0" ixz="0.0" iyy="1.7e-07" iyz="0.0" izz="1.7e-07" />
    </inertial>
  </link>
  <joint name="joint_17" type="revolute">
    <parent link="Sphere_5" />
    <child link="18 L_joint_revolute" />
    <origin xyz="0 0 0" rpy="0 0 0" />
    <axis xyz="0 0 1" rpy="0 -1.55 0" />
    <limit lower="-0.75" upper="0.75" effort="1.0" velocity="1.0" rpy="0 -1.55 0" />
  </joint>
  <link name="18 L_joint_revolute">
    <visual>
      <geometry>
        <cylinder length="0.04" radius="0.02" />
      </geometry>
      <material name="black">
        <color rgba="0.0 0.0 0.0 1.0" />
      </material>
    </visual>
    <collision>
      <geometry>
        <cylinder length="0.04" radius="0.02" />
      </geometry>
    </collision>
    <inertial>
      <mass value="0.05" />
      <inertia ixx="7.5e-06" ixy="0.0" ixz="0.0" iyy="7.5e-06" iyz="0.0" izz="7.5e-06" />
    </inertial>
  </link>
  <joint name="joint_18" type="fixed">
    <parent link="18 L_joint_revolute" />
    <child link="blackSphere_1" />
    <origin xyz="0 0 0" rpy="0 -1.6 0" />
  </joint>
  <link name="blackSphere_1">
    <visual>
      <geometry>
        <cylinder length="0.04" radius="0.009" />
      </geometry>
      <material name="black">
        <color rgba="0.0 0.0 0.0 1.0" />
      </material>
    </visual>
    <collision>
      <geometry>
        <cylinder length="0.04" radius="0.009" />
      </geometry>
    </collision>
    <inertial>
      <mass value="0.065" />
      <inertia ixx="0.0025" ixy="0.0" ixz="0.0" iyy="0.0025" iyz="0.0" izz="0.0025" />
    </inertial>
  </link>
  <joint name="joint_22" type="fixed">
    <parent link="blackSphere_1" />
    <child link="19 wheel_link" />
    <origin xyz="0 0 0.02" rpy="0 0 0" />
  </joint>
  <link name="19 wheel_link">
    <visual>
      <geometry>
        <cylinder length="0.012" radius="0.033" />
      </geometry>
      <material name="green">
        <color rgba="0.0 1.0 0.0 1.0" />
      </material>
    </visual>
    <collision>
      <geometry>
        <cylinder length="0.012" radius="0.033" />
      </geometry>
    </collision>
    <inertial>
      <mass value="0.065" />
      <inertia ixx="0.00001848" ixy="0.0" ixz="0.0" iyy="0.00001848" iyz="0.0" izz="0.00003539" />
    </inertial>
  </link>
  <joint name="joint_24" type="fixed">
    <parent link="17 body_Link_CUBE" />
    <child link="Sphere_7" />
    <origin xyz="0 0 0.023" rpy="0 0 0" />
  </joint>
  <link name="Sphere_7">
    <visual>
      <geometry>
        <sphere radius="0.01" />
      </geometry>
      <material name="black">
        <color rgba="0 0 0 1.0" />
      </material>
    </visual>
    <collision>
      <geometry>
        <sphere radius="0.01" />
      </geometry>
    </collision>
    <inertial>
      <mass value="0.004" />
      <inertia ixx="1.7e-07" ixy="0.0" ixz="0.0" iyy="1.7e-07" iyz="0.0" izz="1.7e-07" />
    </inertial>
  </link>
  <joint name="joint_25" type="revolute">
    <parent link="Sphere_7" />
    <child link="21 B_joint_revolute" />
    <origin xyz="0 0 0" rpy="1.55 0 0" />
    <axis xyz="0 0 1" />
    <limit lower="-1" upper="1" effort="1.0" velocity="1.0" />
  </joint>
  <link name="21 B_joint_revolute">
    <visual>
      <geometry>
        <cylinder length="0.04" radius="0.02" />
      </geometry>
      <material name="black">
        <color rgba="0.0 0.0 0.0 1.0" />
      </material>
    </visual>
    <collision>
      <geometry>
        <cylinder length="0.04" radius="0.02" />
      </geometry>
    </collision>
    <inertial>
      <mass value="0.05" />
      <inertia ixx="7.5e-06" ixy="0.0" ixz="0.0" iyy="7.5e-06" iyz="0.0" izz="7.5e-06" />
    </inertial>
  </link>
  <joint name="joint_26" type="fixed">
    <parent link="21 B_joint_revolute" />
    <child link="Sphere_8" />
    <origin xyz="0 0.02 0" rpy="0 0 0" />
  </joint>
  <link name="Sphere_8">
    <visual>
      <geometry>
        <sphere radius="0.01" />
      </geometry>
      <material name="black">
        <color rgba="0 0 0 1" />
      </material>
    </visual>
    <collision>
      <geometry>
        <sphere radius="0.01" />
      </geometry>
    </collision>
    <inertial>
      <mass value="0.004" />
      <inertia ixx="1.7e-07" ixy="0.0" ixz="0.0" iyy="1.7e-07" iyz="0.0" izz="1.7e-07" />
    </inertial>
  </link>
  <joint name="joint_27" type="fixed">
    <parent link="Sphere_8" />
    <child link="22 body_Link_CUBE" />
    <origin xyz="0 0.025 0" rpy="0 0 0" />
  </joint>
  <link name="22 body_Link_CUBE">
    <visual>
      <geometry>
        <box size="0.046 0.046 0.046" />
      </geometry>
      <material name="red">
        <color rgba="1.0 0.0 0.0 1.0" />
      </material>
    </visual>
    <collision>
      <geometry>
        <box size="0.046 0.046 0.046" />
      </geometry>
    </collision>
    <inertial>
      <mass value="0.1" />
      <inertia ixx="0.0000353" ixy="0.0" ixz="0.0" iyy="0.0000353" iyz="0.0" izz="0.0000353" />
    </inertial>
  </link>
  <joint name="joint_32" type="fixed">
    <parent link="17 body_Link_CUBE" />
    <child link="Sphere_11" />
    <origin xyz="0 0.023 0" rpy="0 0 0" />
  </joint>
  <link name="Sphere_11">
    <visual>
      <geometry>
        <sphere radius="0.01" />
      </geometry>
      <material name="black">
        <color rgba="0 0 0 1.0" />
      </material>
    </visual>
    <collision>
      <geometry>
        <sphere radius="0.01" />
      </geometry>
    </collision>
    <inertial>
      <mass value="0.004" />
      <inertia ixx="1.7e-07" ixy="0.0" ixz="0.0" iyy="1.7e-07" iyz="0.0" izz="1.7e-07" />
    </inertial>
  </link>
  <joint name="joint_33" type="revolute">
    <parent link="Sphere_11" />
    <child link="29 B_joint_revolute" />
    <origin xyz="0 0 0" rpy="0 0 0" />
    <axis xyz="0 0 1" />
    <limit lower="-1" upper="1" effort="1.0" velocity="1.0" />
  </joint>
  <link name="29 B_joint_revolute">
    <visual>
      <geometry>
        <cylinder length="0.04" radius="0.02" />
      </geometry>
      <material name="black">
        <color rgba="0.0 0.0 0.0 1.0" />
      </material>
    </visual>
    <collision>
      <geometry>
        <cylinder length="0.04" radius="0.02" />
      </geometry>
    </collision>
    <inertial>
      <mass value="0.05" />
      <inertia ixx="7.5e-06" ixy="0.0" ixz="0.0" iyy="7.5e-06" iyz="0.0" izz="7.5e-06" />
    </inertial>
  </link>
  <joint name="joint_34" type="fixed">
    <parent link="29 B_joint_revolute" />
    <child link="Sphere_12" />
    <origin xyz="0 0.02 0" rpy="0 0 0" />
  </joint>
  <link name="Sphere_12">
    <visual>
      <geometry>
        <sphere radius="0.01" />
      </geometry>
      <material name="black">
        <color rgba="0 0 0 1" />
      </material>
    </visual>
    <collision>
      <geometry>
        <sphere radius="0.01" />
      </geometry>
    </collision>
    <inertial>
      <mass value="0.004" />
      <inertia ixx="1.7e-07" ixy="0.0" ixz="0.0" iyy="1.7e-07" iyz="0.0" izz="1.7e-07" />
    </inertial>
  </link>
  <joint name="joint_35" type="fixed">
    <parent link="Sphere_12" />
    <child link="30 body_Link_CUBE" />
    <origin xyz="0 0.025 0" rpy="0 0 0" />
  </joint>
  <link name="30 body_Link_CUBE">
    <visual>
      <geometry>
        <box size="0.046 0.046 0.046" />
      </geometry>
      <material name="red">
        <color rgba="1.0 0.0 0.0 1.0" />
      </material>
    </visual>
    <collision>
      <geometry>
        <box size="0.046 0.046 0.046" />
      </geometry>
    </collision>
    <inertial>
      <mass value="0.1" />
      <inertia ixx="0.0000353" ixy="0.0" ixz="0.0" iyy="0.0000353" iyz="0.0" izz="0.0000353" />
    </inertial>
  </link>
  <joint name="joint_40" type="fixed">
    <parent link="17 body_Link_CUBE" />
    <child link="Sphere_15" />
    <origin xyz="0.023 0 0" rpy="0 0 0" />
  </joint>
  <link name="Sphere_15">
    <visual>
      <geometry>
        <sphere radius="0.01" />
      </geometry>
      <material name="black">
        <color rgba="0 0 0 1.0" />
      </material>
    </visual>
    <collision>
      <geometry>
        <sphere radius="0.01" />
      </geometry>
    </collision>
    <inertial>
      <mass value="0.004" />
      <inertia ixx="1.7e-07" ixy="0.0" ixz="0.0" iyy="1.7e-07" iyz="0.0" izz="1.7e-07" />
    </inertial>
  </link>
  <joint name="joint_41" type="continuous">
    <parent link="Sphere_15" />
    <child link="36 B_joint_continuous" />
    <origin xyz="0 0 0" rpy="0 1.55 0" />
    <axis xyz="0 0 1" />
    <limit effort="1.0" velocity="1.0" rpy="0 3.15 0" />
  </joint>
  <link name="36 B_joint_continuous">
    <visual>
      <geometry>
        <cylinder length="0.04" radius="0.02" />
      </geometry>
      <material name="black">
        <color rgba="0.0 0.0 0.0 1.0" />
      </material>
    </visual>
    <collision>
      <geometry>
        <cylinder length="0.04" radius="0.02" />
      </geometry>
    </collision>
    <inertial>
      <mass value="0.05" />
      <inertia ixx="7.5e-06" ixy="0.0" ixz="0.0" iyy="7.5e-06" iyz="0.0" izz="7.5e-06" />
    </inertial>
  </link>
  <joint name="joint_42" type="fixed">
    <parent link="36 B_joint_continuous" />
    <child link="37 body_Link_CUBE" />
    <origin xyz="0 0 0.035" rpy="0 0 0" />
  </joint>
  <link name="37 body_Link_CUBE">
    <visual>
      <geometry>
        <box size="0.046 0.046 0.046" />
      </geometry>
      <material name="red">
        <color rgba="1.0 0.0 0.0 1.0" />
      </material>
    </visual>
    <collision>
      <geometry>
        <box size="0.046 0.046 0.046" />
      </geometry>
    </collision>
    <inertial>
      <mass value="0.1" />
      <inertia ixx="0.0000353" ixy="0.0" ixz="0.0" iyy="0.0000353" iyz="0.0" izz="0.0000353" />
    </inertial>
  </link>
</robot>