<?xml version='1.0' encoding='utf-8'?>
<robot name="combined_robot_GEN_0_number_3">
  <link name="0 body_Link_CUBE">
    <visual>
      <geometry>
        <box size="0.046 0.046 0.046" />
      </geometry>
      <material name="red">
        <color rgba="1.0 0.0 0.0 1.0" />
      </material>
    </visual>
    <collision>
      <geometry>
        <box size="0.046 0.046 0.046" />
      </geometry>
    </collision>
    <inertial>
      <mass value="0.1" />
      <inertia ixx="0.0000353" ixy="0.0" ixz="0.0" iyy="0.0000353" iyz="0.0" izz="0.0000353" />
    </inertial>
  </link>
  <joint name="joint_0" type="fixed">
    <parent link="0 body_Link_CUBE" />
    <child link="Sphere_0" />
    <origin xyz="0 0 -0.023" rpy="0 0 0" />
  </joint>
  <link name="Sphere_0">
    <visual>
      <geometry>
        <sphere radius="0.01" />
      </geometry>
      <material name="black">
        <color rgba="0 0 0 1" />
      </material>
    </visual>
    <collision>
      <geometry>
        <sphere radius="0.01" />
      </geometry>
    </collision>
    <inertial>
      <mass value="0.004" />
      <inertia ixx="1.7e-07" ixy="0.0" ixz="0.0" iyy="1.7e-07" iyz="0.0" izz="1.7e-07" />
    </inertial>
  </link>
  <joint name="joint_1" type="continuous">
    <parent link="Sphere_0" />
    <child link="1 B_joint_continuous" />
    <origin xyz="0 0 0" rpy="0 0 0" />
    <axis xyz="0 0 1" />
    <limit effort="1.0" velocity="1.0" rpy="0 3.15 0" />
  </joint>
  <link name="1 B_joint_continuous">
    <visual>
      <geometry>
        <cylinder length="0.04" radius="0.02" />
      </geometry>
      <material name="black">
        <color rgba="0.0 0.0 0.0 1.0" />
      </material>
    </visual>
    <collision>
      <geometry>
        <cylinder length="0.04" radius="0.02" />
      </geometry>
    </collision>
    <inertial>
      <mass value="0.05" />
      <inertia ixx="7.5e-06" ixy="0.0" ixz="0.0" iyy="7.5e-06" iyz="0.0" izz="7.5e-06" />
    </inertial>
  </link>
  <joint name="joint_2" type="fixed">
    <parent link="1 B_joint_continuous" />
    <child link="2 body_Link_CUBE" />
    <origin xyz="0 0 -0.035" rpy="0 0 0" />
  </joint>
  <link name="2 body_Link_CUBE">
    <visual>
      <geometry>
        <box size="0.046 0.046 0.046" />
      </geometry>
      <material name="red">
        <color rgba="1.0 0.0 0.0 1.0" />
      </material>
    </visual>
    <collision>
      <geometry>
        <box size="0.046 0.046 0.046" />
      </geometry>
    </collision>
    <inertial>
      <mass value="0.1" />
      <inertia ixx="0.0000353" ixy="0.0" ixz="0.0" iyy="0.0000353" iyz="0.0" izz="0.0000353" />
    </inertial>
  </link>
  <joint name="joint_3" type="fixed">
    <parent link="0 body_Link_CUBE" />
    <child link="Sphere_1" />
    <origin xyz="0 -0.023 0" rpy="0 0 0" />
  </joint>
  <link name="Sphere_1">
    <visual>
      <geometry>
        <sphere radius="0.01" />
      </geometry>
      <material name="black">
        <color rgba="0 0 0 1.0" />
      </material>
    </visual>
    <collision>
      <geometry>
        <sphere radius="0.01" />
      </geometry>
    </collision>
    <inertial>
      <mass value="0.004" />
      <inertia ixx="1.7e-07" ixy="0.0" ixz="0.0" iyy="1.7e-07" iyz="0.0" izz="1.7e-07" />
    </inertial>
  </link>
  <joint name="joint_4" type="fixed">
    <parent link="Sphere_1" />
    <child link="9 B_joint_fixed" />
    <origin xyz="0 0 0" rpy="0 0 0" />
  </joint>
  <link name="9 B_joint_fixed">
    <visual>
      <geometry>
        <box size="0.03 0.03 0.03" />
      </geometry>
      <material name="black">
        <color rgba="0.0 0.0 0.0 1.0" />
      </material>
    </visual>
    <collision>
      <geometry>
        <box size="0.03 0.03 0.03" />
      </geometry>
    </collision>
    <inertial>
      <mass value="0.05" />
      <inertia ixx="7.5e-06" ixy="0.0" ixz="0.0" iyy="7.5e-06" iyz="0.0" izz="7.5e-06" />
    </inertial>
  </link>
  <joint name="joint_5" type="fixed">
    <parent link="9 B_joint_fixed" />
    <child link="10 body_Link_CUBE" />
    <origin xyz="0 -0.03 0" rpy="0 0 0" />
  </joint>
  <link name="10 body_Link_CUBE">
    <visual>
      <geometry>
        <box size="0.046 0.046 0.046" />
      </geometry>
      <material name="red">
        <color rgba="1.0 0.0 0.0 1.0" />
      </material>
    </visual>
    <collision>
      <geometry>
        <box size="0.046 0.046 0.046" />
      </geometry>
    </collision>
    <inertial>
      <mass value="0.1" />
      <inertia ixx="0.0000353" ixy="0.0" ixz="0.0" iyy="0.0000353" iyz="0.0" izz="0.0000353" />
    </inertial>
  </link>
</robot>